<mujoco model="dual_xarm7">
  <compiler angle="radian" autolimits="true" meshdir="assets"/>
  
  <option timestep="0.002" gravity="0 0 -9.81" integrator="RK4"/>
  
  <asset>
    <texture name="grid" type="2d" builtin="checker" rgb1=".1 .2 .3" rgb2=".2 .3 .4" width="300" height="300"/>
    <material name="grid" texture="grid" texrepeat="8 8" reflectance=".2"/>
    
    <material name="white" rgba="1 1 1 1"/>
    <material name="gray" rgba="0.753 0.753 0.753 1"/>
    <material name="black" rgba="0.149 0.149 0.149 1"/>
    <material name="plastic" rgba="0.9 0.9 0.9 1"/>

    <!-- XArm-7 meshes -->
    <mesh file="link_base.stl"/>
    <mesh file="link1.stl"/>
    <mesh file="link2.stl"/>
    <mesh file="link3.stl"/>
    <mesh file="link4.stl"/>
    <mesh file="link5.stl"/>
  <mesh file="link6.stl"/>
  <mesh file="link7.stl"/>
  <mesh file="end_tool.stl"/>
  <!-- Robotiq 2F85 official meshes -->
  <mesh class="2f85" file="base_mount.stl"/>
  <mesh class="2f85" file="base.stl"/>
  <mesh class="2f85" file="driver.stl"/>
  <mesh class="2f85" file="coupler.stl"/>
  <mesh class="2f85" file="follower.stl"/>
  <mesh class="2f85" file="pad.stl"/>
  <mesh class="2f85" file="silicone_pad.stl"/>
  <mesh class="2f85" file="spring_link.stl"/>
  </asset>

  <default>
    <default class="xarm7">
      <geom type="mesh" material="white"/>
      <joint axis="0 0 1" armature="0.1" range="-6.28319 6.28319" frictionloss="1"/>
      <general biastype="affine" ctrlrange="-6.28319 6.28319"/>
      <default class="size1">
        <joint damping="10"/>
        <general gainprm="1500" biasprm="0 -1500 -150" forcerange="-50 50"/>
      </default>
      <default class="size2">
        <joint damping="5"/>
        <general gainprm="1000" biasprm="0 -1000 -100" forcerange="-30 30"/>
      </default>
      <default class="size3">
        <joint damping="2"/>
        <general gainprm="800" biasprm="0 -800 -80" forcerange="-20 20"/>
      </default>
      <!-- XArm wrist site -->
      <site size="0.001" rgba="1 0 0 1" group="4"/>
    </default>
    <!-- 2F85 defaults (imported) -->
    <default class="2f85">
      <mesh scale="0.001 0.001 0.001"/>
      <general biastype="affine"/>
      <joint axis="1 0 0"/>
      <default class="driver">
        <joint range="0 0.8" armature="0.005" damping="0.1" solimplimit="0.95 0.99 0.001" solreflimit="0.005 1"/>
      </default>
      <default class="follower">
        <joint range="-0.872664 0.872664" armature="0.001" pos="0 -0.018 0.0065" solimplimit="0.95 0.99 0.001" solreflimit="0.005 1"/>
      </default>
      <default class="spring_link">
        <joint range="-0.29670597283 0.8" armature="0.001" stiffness="0.05" springref="2.62" damping="0.00125"/>
      </default>
      <default class="coupler">
        <joint range="-1.57 0" armature="0.001" solimplimit="0.95 0.99 0.001" solreflimit="0.005 1"/>
      </default>
      <default class="visual">
        <geom type="mesh" contype="0" conaffinity="0" group="2"/>
      </default>
      <default class="collision">
        <geom type="mesh" group="3"/>
        <default class="pad_box1">
          <geom mass="0" type="box" pos="0 -0.0026 0.028125" size="0.011 0.004 0.009375" friction="0.7" solimp="0.95 0.99 0.001" solref="0.004 1" priority="1" rgba="0.55 0.55 0.55 1"/>
        </default>
        <default class="pad_box2">
          <geom mass="0" type="box" pos="0 -0.0026 0.009375" size="0.011 0.004 0.009375" friction="0.6" solimp="0.95 0.99 0.001" solref="0.004 1" priority="1" rgba="0.45 0.45 0.45 1"/>
        </default>
      </default>
    </default>
  </default>

  <worldbody>
    <!-- Ground plane -->
    <geom name="floor" size="0 0 0.125" type="plane" material="grid"/>
    
    <!-- Robot base table (底座桌子) -->
    <body name="base_table" pos="0 0 0.43">
      <geom name="base_table_geom" type="box" size="0.30 0.10 0.02" rgba="0.4 0.4 0.4 1" material="plastic"/>
    </body>
    
    <!-- Work table (工作桌面，比底座高8cm) -->
    <body name="work_table" pos="0 0.5 0.30">
      <geom name="work_table_geom" type="box" size="0.8 0.4 0.02" rgba="0.6 0.4 0.2 1" material="plastic"/>
    </body>
    
    <!-- Left XArm-7 (底座中心点在0.235, 0, 0.42, 朝向前方桌子) -->
    <body name="left_base" pos="0.235 0 0.42" quat="0.7071068 0 0 0.7071068" childclass="xarm7">
      <inertial pos="-0.021131 -0.0016302 0.056488" quat="0.696843 0.20176 0.10388 0.680376" mass="0.88556"
        diaginertia="0.00382023 0.00335282 0.00167725"/>
      <geom mesh="link_base"/>
      <body name="left_link1" pos="0 0 0.267">
        <inertial pos="-0.0002 0.02905 -0.01233" quat="0.978953 -0.202769 -0.00441617 -0.0227264" mass="2.382"
          diaginertia="0.00569127 0.00533384 0.00293865"/>
        <joint name="left_joint1" class="size1"/>
        <geom mesh="link1"/>
        <body name="left_link2" quat="1 -1 0 0">
          <inertial pos="0.00022 -0.12856 0.01735" quat="0.50198 0.86483 -0.00778841 0.00483285" mass="1.869"
            diaginertia="0.00959898 0.00937717 0.00201315"/>
          <joint name="left_joint2" range="-2.059 2.0944" class="size1"/>
          <geom mesh="link2"/>
          <body name="left_link3" pos="0 -0.293 0" quat="1 1 0 0">
            <inertial pos="0.0466 -0.02463 -0.00768" quat="0.913819 0.289775 0.281481 -0.0416455" mass="1.6383"
              diaginertia="0.00351721 0.00294089 0.00195868"/>
            <joint name="left_joint3" class="size2"/>
            <geom mesh="link3"/>
            <body name="left_link4" pos="0.0525 0 0" quat="1 1 0 0">
              <inertial pos="0.07047 -0.11575 0.012" quat="0.422108 0.852026 -0.126025 0.282832" mass="1.7269"
                diaginertia="0.00657137 0.00647948 0.00186763"/>
              <joint name="left_joint4" range="-0.19198 3.927" class="size2"/>
              <geom mesh="link4"/>
              <body name="left_link5" pos="0.0775 -0.3425 0" quat="1 1 0 0">
                <inertial pos="-0.00032 0.01604 -0.026" quat="0.999311 -0.0304457 0.000577067 0.0212082" mass="1.3203"
                  diaginertia="0.00534729 0.00499076 0.0013489"/>
                <joint name="left_joint5" class="size2"/>
                <geom mesh="link5"/>
                <body name="left_link6" quat="1 1 0 0">
                  <inertial pos="0.06469 0.03278 0.02141" quat="-0.217672 0.772419 0.16258 0.574069" mass="1.325"
                    diaginertia="0.00245421 0.00221646 0.00107273"/>
                  <joint name="left_joint6" range="-1.69297 3.14159" class="size3"/>
                  <geom mesh="link6"/>
                  <body name="left_link7" pos="0.076 0.097 0" quat="1 -1 0 0">
                    <inertial pos="0 -0.00677 -0.01098" quat="0.487612 0.512088 -0.512088 0.487612" mass="0.17"
                      diaginertia="0.000132176 9.3e-05 5.85236e-05"/>
                    <joint name="left_joint7" range="-6.28319 6.28319" class="size3"/>
                    <geom material="gray" mesh="end_tool"/>
                    <!-- Official 2F85 assembly (Left) -->
                    <body name="left_base_mount" pos="0 0 0" childclass="2f85">
                      <geom class="visual" mesh="base_mount" material="black"/>
                      <geom class="collision" mesh="base_mount"/>
                      <body name="left_gripper_base" pos="0 0 0.0038" quat="0 0 0 1">
                        <inertial mass="0.777441" pos="0 -2.70394e-05 0.0354675" quat="1 -0.00152849 0 0" diaginertia="0.000260285 0.000225381 0.000152708"/>
                        <geom class="visual" mesh="base" material="black"/>
                        <geom class="collision" mesh="base"/>
                        <site name="left_pinch" pos="0 0 0.145" type="sphere" group="5" rgba="0.9 0.9 0.9 1" size="0.005"/>
                        <!-- Right linkage -->
                        <body name="left_right_driver" pos="0 0.0306011 0.054904">
                          <inertial mass="0.00899563" pos="2.96931e-12 0.0177547 0.00107314" quat="0.681301 0.732003 0 0" diaginertia="1.72352e-06 1.60906e-06 3.22006e-07"/>
                          <joint name="left_right_driver_joint" class="driver"/>
                          <geom class="visual" mesh="driver" material="gray"/>
                          <geom class="collision" mesh="driver"/>
                          <body name="left_right_coupler" pos="0 0.0315 -0.0041">
                            <inertial mass="0.0140974" pos="0 0.00301209 0.0232175" quat="0.705636 -0.0455904 0.0455904 0.705636" diaginertia="4.16206e-06 3.52216e-06 8.88131e-07"/>
                            <joint name="left_right_coupler_joint" class="coupler"/>
                            <geom class="visual" mesh="coupler" material="black"/>
                            <geom class="collision" mesh="coupler"/>
                          </body>
                        </body>
                        <body name="left_right_spring_link" pos="0 0.0132 0.0609">
                          <inertial mass="0.0221642" pos="-8.65005e-09 0.0181624 0.0212658" quat="0.663403 -0.244737 0.244737 0.663403" diaginertia="8.96853e-06 6.71733e-06 2.63931e-06"/>
                          <joint name="left_right_spring_link_joint" class="spring_link"/>
                          <geom class="visual" mesh="spring_link" material="black"/>
                          <geom class="collision" mesh="spring_link"/>
                          <body name="left_right_follower" pos="0 0.055 0.0375">
                            <inertial mass="0.0125222" pos="0 -0.011046 0.0124786" quat="1 0.1664 0 0" diaginertia="2.67415e-06 2.4559e-06 6.02031e-07"/>
                            <joint name="left_right_follower_joint" class="follower"/>
                            <geom class="visual" mesh="follower" material="black"/>
                            <geom class="collision" mesh="follower"/>
                            <body name="left_right_pad" pos="0 -0.0189 0.01352">
                              <geom class="pad_box1" name="left_right_pad1"/>
                              <geom class="pad_box2" name="left_right_pad2"/>
                              <inertial mass="0.0035" pos="0 -0.0025 0.0185" quat="0.707107 0 0 0.707107" diaginertia="4.73958e-07 3.64583e-07 1.23958e-07"/>
                              <geom class="visual" mesh="pad"/>
                              <body name="left_right_silicone_pad">
                                <geom class="visual" mesh="silicone_pad" material="black"/>
                              </body>
                            </body>
                          </body>
                        </body>
                        <!-- Left linkage -->
                        <body name="left_left_driver" pos="0 -0.0306011 0.054904" quat="0 0 0 1">
                          <inertial mass="0.00899563" pos="0 0.0177547 0.00107314" quat="0.681301 0.732003 0 0" diaginertia="1.72352e-06 1.60906e-06 3.22006e-07"/>
                          <joint name="left_left_driver_joint" class="driver"/>
                          <geom class="visual" mesh="driver" material="gray"/>
                          <geom class="collision" mesh="driver"/>
                          <body name="left_left_coupler" pos="0 0.0315 -0.0041">
                            <inertial mass="0.0140974" pos="0 0.00301209 0.0232175" quat="0.705636 -0.0455904 0.0455904 0.705636" diaginertia="4.16206e-06 3.52216e-06 8.88131e-07"/>
                            <joint name="left_left_coupler_joint" class="coupler"/>
                            <geom class="visual" mesh="coupler" material="black"/>
                            <geom class="collision" mesh="coupler"/>
                          </body>
                        </body>
                        <body name="left_left_spring_link" pos="0 -0.0132 0.0609" quat="0 0 0 1">
                          <inertial mass="0.0221642" pos="-8.65005e-09 0.0181624 0.0212658" quat="0.663403 -0.244737 0.244737 0.663403" diaginertia="8.96853e-06 6.71733e-06 2.63931e-06"/>
                          <joint name="left_left_spring_link_joint" class="spring_link"/>
                          <geom class="visual" mesh="spring_link" material="black"/>
                          <geom class="collision" mesh="spring_link"/>
                          <body name="left_left_follower" pos="0 0.055 0.0375">
                            <inertial mass="0.0125222" pos="0 -0.011046 0.0124786" quat="1 0.1664 0 0" diaginertia="2.67415e-06 2.4559e-06 6.02031e-07"/>
                            <joint name="left_left_follower_joint" class="follower"/>
                            <geom class="visual" mesh="follower" material="black"/>
                            <geom class="collision" mesh="follower"/>
                            <body name="left_left_pad" pos="0 -0.0189 0.01352">
                              <geom class="pad_box1" name="left_left_pad1"/>
                              <geom class="pad_box2" name="left_left_pad2"/>
                              <inertial mass="0.0035" pos="0 -0.0025 0.0185" quat="1 0 0 1" diaginertia="4.73958e-07 3.64583e-07 1.23958e-07"/>
                              <geom class="visual" mesh="pad"/>
                              <body name="left_left_silicone_pad">
                                <geom class="visual" mesh="silicone_pad" material="black"/>
                              </body>
                            </body>
                          </body>
                        </body>
                      </body>
                    </body>
                  </body>
                </body>
              </body>
            </body>
          </body>
        </body>
      </body>
    </body>
    
    <!-- Right XArm-7 (底座中心点在-0.235, 0, 0.42，相距47cm, 朝向前方桌子) -->
    <body name="right_base" pos="-0.235 0 0.42" quat="0.7071068 0 0 0.7071068" childclass="xarm7">
      <inertial pos="-0.021131 -0.0016302 0.056488" quat="0.696843 0.20176 0.10388 0.680376" mass="0.88556"
        diaginertia="0.00382023 0.00335282 0.00167725"/>
      <geom mesh="link_base"/>
      <body name="right_link1" pos="0 0 0.267">
        <inertial pos="-0.0002 0.02905 -0.01233" quat="0.978953 -0.202769 -0.00441617 -0.0227264" mass="2.382"
          diaginertia="0.00569127 0.00533384 0.00293865"/>
        <joint name="right_joint1" class="size1"/>
        <geom mesh="link1"/>
        <body name="right_link2" quat="1 -1 0 0">
          <inertial pos="0.00022 -0.12856 0.01735" quat="0.50198 0.86483 -0.00778841 0.00483285" mass="1.869"
            diaginertia="0.00959898 0.00937717 0.00201315"/>
          <joint name="right_joint2" range="-2.059 2.0944" class="size1"/>
          <geom mesh="link2"/>
          <body name="right_link3" pos="0 -0.293 0" quat="1 1 0 0">
            <inertial pos="0.0466 -0.02463 -0.00768" quat="0.913819 0.289775 0.281481 -0.0416455" mass="1.6383"
              diaginertia="0.00351721 0.00294089 0.00195868"/>
            <joint name="right_joint3" class="size2"/>
            <geom mesh="link3"/>
            <body name="right_link4" pos="0.0525 0 0" quat="1 1 0 0">
              <inertial pos="0.07047 -0.11575 0.012" quat="0.422108 0.852026 -0.126025 0.282832" mass="1.7269"
                diaginertia="0.00657137 0.00647948 0.00186763"/>
              <joint name="right_joint4" range="-0.19198 3.927" class="size2"/>
              <geom mesh="link4"/>
              <body name="right_link5" pos="0.0775 -0.3425 0" quat="1 1 0 0">
                <inertial pos="-0.00032 0.01604 -0.026" quat="0.999311 -0.0304457 0.000577067 0.0212082" mass="1.3203"
                  diaginertia="0.00534729 0.00499076 0.0013489"/>
                <joint name="right_joint5" class="size2"/>
                <geom mesh="link5"/>
                <body name="right_link6" quat="1 1 0 0">
                  <inertial pos="0.06469 0.03278 0.02141" quat="-0.217672 0.772419 0.16258 0.574069" mass="1.325"
                    diaginertia="0.00245421 0.00221646 0.00107273"/>
                  <joint name="right_joint6" range="-1.69297 3.14159" class="size3"/>
                  <geom mesh="link6"/>
                  <body name="right_link7" pos="0.076 0.097 0" quat="1 -1 0 0">
                    <inertial pos="0 -0.00677 -0.01098" quat="0.487612 0.512088 -0.512088 0.487612" mass="0.17"
                      diaginertia="0.000132176 9.3e-05 5.85236e-05"/>
                    <joint name="right_joint7" range="-6.28319 6.28319" class="size3"/>
                    <geom material="gray" mesh="end_tool"/>
                    <!-- Official 2F85 assembly (Right) -->
                    <body name="right_base_mount" pos="0 0 0" childclass="2f85">
                      <geom class="visual" mesh="base_mount" material="black"/>
                      <geom class="collision" mesh="base_mount"/>
                      <body name="right_gripper_base" pos="0 0 0.0038" quat="0 0 0 1">
                        <inertial mass="0.777441" pos="0 -2.70394e-05 0.0354675" quat="1 -0.00152849 0 0" diaginertia="0.000260285 0.000225381 0.000152708"/>
                        <geom class="visual" mesh="base" material="black"/>
                        <geom class="collision" mesh="base"/>
                        <site name="right_pinch" pos="0 0 0.145" type="sphere" group="5" rgba="0.9 0.9 0.9 1" size="0.005"/>
                        <!-- Right linkage -->
                        <body name="right_right_driver" pos="0 0.0306011 0.054904">
                          <inertial mass="0.00899563" pos="2.96931e-12 0.0177547 0.00107314" quat="0.681301 0.732003 0 0" diaginertia="1.72352e-06 1.60906e-06 3.22006e-07"/>
                          <joint name="right_right_driver_joint" class="driver"/>
                          <geom class="visual" mesh="driver" material="gray"/>
                          <geom class="collision" mesh="driver"/>
                          <body name="right_right_coupler" pos="0 0.0315 -0.0041">
                            <inertial mass="0.0140974" pos="0 0.00301209 0.0232175" quat="0.705636 -0.0455904 0.0455904 0.705636" diaginertia="4.16206e-06 3.52216e-06 8.88131e-07"/>
                            <joint name="right_right_coupler_joint" class="coupler"/>
                            <geom class="visual" mesh="coupler" material="black"/>
                            <geom class="collision" mesh="coupler"/>
                          </body>
                        </body>
                        <body name="right_right_spring_link" pos="0 0.0132 0.0609">
                          <inertial mass="0.0221642" pos="-8.65005e-09 0.0181624 0.0212658" quat="0.663403 -0.244737 0.244737 0.663403" diaginertia="8.96853e-06 6.71733e-06 2.63931e-06"/>
                          <joint name="right_right_spring_link_joint" class="spring_link"/>
                          <geom class="visual" mesh="spring_link" material="black"/>
                          <geom class="collision" mesh="spring_link"/>
                          <body name="right_right_follower" pos="0 0.055 0.0375">
                            <inertial mass="0.0125222" pos="0 -0.011046 0.0124786" quat="1 0.1664 0 0" diaginertia="2.67415e-06 2.4559e-06 6.02031e-07"/>
                            <joint name="right_right_follower_joint" class="follower"/>
                            <geom class="visual" mesh="follower" material="black"/>
                            <geom class="collision" mesh="follower"/>
                            <body name="right_right_pad" pos="0 -0.0189 0.01352">
                              <geom class="pad_box1" name="right_right_pad1"/>
                              <geom class="pad_box2" name="right_right_pad2"/>
                              <inertial mass="0.0035" pos="0 -0.0025 0.0185" quat="0.707107 0 0 0.707107" diaginertia="4.73958e-07 3.64583e-07 1.23958e-07"/>
                              <geom class="visual" mesh="pad"/>
                              <body name="right_right_silicone_pad">
                                <geom class="visual" mesh="silicone_pad" material="black"/>
                              </body>
                            </body>
                          </body>
                        </body>
                        <!-- Left linkage -->
                        <body name="right_left_driver" pos="0 -0.0306011 0.054904" quat="0 0 0 1">
                          <inertial mass="0.00899563" pos="0 0.0177547 0.00107314" quat="0.681301 0.732003 0 0" diaginertia="1.72352e-06 1.60906e-06 3.22006e-07"/>
                          <joint name="right_left_driver_joint" class="driver"/>
                          <geom class="visual" mesh="driver" material="gray"/>
                          <geom class="collision" mesh="driver"/>
                          <body name="right_left_coupler" pos="0 0.0315 -0.0041">
                            <inertial mass="0.0140974" pos="0 0.00301209 0.0232175" quat="0.705636 -0.0455904 0.0455904 0.705636" diaginertia="4.16206e-06 3.52216e-06 8.88131e-07"/>
                            <joint name="right_left_coupler_joint" class="coupler"/>
                            <geom class="visual" mesh="coupler" material="black"/>
                            <geom class="collision" mesh="coupler"/>
                          </body>
                        </body>
                        <body name="right_left_spring_link" pos="0 -0.0132 0.0609" quat="0 0 0 1">
                          <inertial mass="0.0221642" pos="-8.65005e-09 0.0181624 0.0212658" quat="0.663403 -0.244737 0.244737 0.663403" diaginertia="8.96853e-06 6.71733e-06 2.63931e-06"/>
                          <joint name="right_left_spring_link_joint" class="spring_link"/>
                          <geom class="visual" mesh="spring_link" material="black"/>
                          <geom class="collision" mesh="spring_link"/>
                          <body name="right_left_follower" pos="0 0.055 0.0375">
                            <inertial mass="0.0125222" pos="0 -0.011046 0.0124786" quat="1 0.1664 0 0" diaginertia="2.67415e-06 2.4559e-06 6.02031e-07"/>
                            <joint name="right_left_follower_joint" class="follower"/>
                            <geom class="visual" mesh="follower" material="black"/>
                            <geom class="collision" mesh="follower"/>
                            <body name="right_left_pad" pos="0 -0.0189 0.01352">
                              <geom class="pad_box1" name="right_left_pad1"/>
                              <geom class="pad_box2" name="right_left_pad2"/>
                              <inertial mass="0.0035" pos="0 -0.0025 0.0185" quat="1 0 0 1" diaginertia="4.73958e-07 3.64583e-07 1.23958e-07"/>
                              <geom class="visual" mesh="pad"/>
                              <body name="right_left_silicone_pad">
                                <geom class="visual" mesh="silicone_pad" material="black"/>
                              </body>
                            </body>
                          </body>
                        </body>
                      </body>
                    </body>
                  </body>
                </body>
              </body>
            </body>
          </body>
        </body>
      </body>
    </body>
    
    <!-- Objects on work table -->
    <body name="object1" pos="0.08 0.6 0.53">
      <geom name="obj1_geom" type="box" size="0.03 0.03 0.03" rgba="0.8 0.2 0.2 1"/>
      <joint name="obj1_freejoint" type="free"/>
    </body>
    
    <body name="object2" pos="-0.08 0.6 0.53">
      <geom name="obj2_geom" type="cylinder" size="0.025 0.05" rgba="0.2 0.8 0.2 1"/>
      <joint name="obj2_freejoint" type="free"/>
    </body>
  </worldbody>
  
  <!-- Cameras -->
  <worldbody>
    <!-- Front camera -->
    <body name="front_camera" pos="0 -1.0 1.2" euler="0 0 0">
      <camera name="front_cam" fovy="45"/>
    </body>
    
    <!-- Left wrist camera -->
    <body name="left_wrist_camera" pos="-0.4 0 1.4" euler="1.57 0 -1.57">
      <camera name="left_wrist_cam" fovy="45"/>
    </body>
    
    <!-- Right wrist camera -->
    <body name="right_wrist_camera" pos="0.4 0 1.4" euler="1.57 0 1.57">
      <camera name="right_wrist_cam" fovy="45"/>
    </body>
  </worldbody>
  
  <actuator>
    <!-- Left arm actuators -->
    <general name="left_act1" joint="left_joint1" class="size1"/>
    <general name="left_act2" joint="left_joint2" class="size1" ctrlrange="-2.059 2.0944"/>
    <general name="left_act3" joint="left_joint3" class="size2"/>
    <general name="left_act4" joint="left_joint4" class="size2" ctrlrange="-0.19198 3.927"/>
    <general name="left_act5" joint="left_joint5" class="size2"/>
    <general name="left_act6" joint="left_joint6" class="size3" ctrlrange="-1.69297 3.14159"/>
  <general name="left_act7" joint="left_joint7" class="size3"/>
  <general class="2f85" name="left_gripper_act" tendon="left_gripper_split" forcerange="-5 5" ctrlrange="0 255" gainprm="0.3137255 0 0" biasprm="0 -100 -10"/>
    
    <!-- Right arm actuators -->
    <general name="right_act1" joint="right_joint1" class="size1"/>
    <general name="right_act2" joint="right_joint2" class="size1" ctrlrange="-2.059 2.0944"/>
    <general name="right_act3" joint="right_joint3" class="size2"/>
    <general name="right_act4" joint="right_joint4" class="size2" ctrlrange="-0.19198 3.927"/>
    <general name="right_act5" joint="right_joint5" class="size2"/>
    <general name="right_act6" joint="right_joint6" class="size3" ctrlrange="-1.69297 3.14159"/>
    <general name="right_act7" joint="right_joint7" class="size3"/>
    <general class="2f85" name="right_gripper_act" tendon="right_gripper_split" forcerange="-5 5" ctrlrange="0 255" gainprm="0.3137255 0 0" biasprm="0 -100 -10"/>
  </actuator>
  <!-- 2F85 coupling and constraints -->
  <contact>
  <exclude body1="left_gripper_base" body2="left_left_driver"/>
  <exclude body1="left_gripper_base" body2="left_right_driver"/>
  <exclude body1="left_gripper_base" body2="left_left_spring_link"/>
  <exclude body1="left_gripper_base" body2="left_right_spring_link"/>
    <exclude body1="left_right_coupler" body2="left_right_follower"/>
    <exclude body1="left_left_coupler" body2="left_left_follower"/>
  <exclude body1="right_gripper_base" body2="right_left_driver"/>
  <exclude body1="right_gripper_base" body2="right_right_driver"/>
  <exclude body1="right_gripper_base" body2="right_left_spring_link"/>
  <exclude body1="right_gripper_base" body2="right_right_spring_link"/>
    <exclude body1="right_right_coupler" body2="right_right_follower"/>
    <exclude body1="right_left_coupler" body2="right_left_follower"/>
  </contact>
  <tendon>
    <fixed name="left_gripper_split">
      <joint joint="left_right_driver_joint" coef="0.5"/>
      <joint joint="left_left_driver_joint" coef="0.5"/>
    </fixed>
    <fixed name="right_gripper_split">
      <joint joint="right_right_driver_joint" coef="0.5"/>
      <joint joint="right_left_driver_joint" coef="0.5"/>
    </fixed>
  </tendon>
  <equality>
    <connect anchor="0 0 0" body1="left_right_follower" body2="left_right_coupler" solimp="0.95 0.99 0.001" solref="0.005 1"/>
    <connect anchor="0 0 0" body1="left_left_follower" body2="left_left_coupler" solimp="0.95 0.99 0.001" solref="0.005 1"/>
    <joint joint1="left_right_driver_joint" joint2="left_left_driver_joint" polycoef="0 1 0 0 0" solimp="0.95 0.99 0.001" solref="0.005 1"/>
    <connect anchor="0 0 0" body1="right_right_follower" body2="right_right_coupler" solimp="0.95 0.99 0.001" solref="0.005 1"/>
    <connect anchor="0 0 0" body1="right_left_follower" body2="right_left_coupler" solimp="0.95 0.99 0.001" solref="0.005 1"/>
    <joint joint1="right_right_driver_joint" joint2="right_left_driver_joint" polycoef="0 1 0 0 0" solimp="0.95 0.99 0.001" solref="0.005 1"/>
  </equality>
  
  <!-- 初始关节角度设置 -->
  <keyframe>
    <key name="initial_pose" 
        qpos="0 -0.22 0 0.873 0.0105 1.117 -0.0035
              0 0 0 0 0 0 0 0
              0 -0.22 0 0.873 0.0105 1.117 -0.0035
              0 0 0 0 0 0 0 0
              0.08000 0.60000 0.53000 1.00000 0.00000 0.00000 0.00000
              -0.08000 0.60000 0.53000 1.00000 0.00000 0.00000 0.00000" />
  </keyframe>
</mujoco>
